Workbook

Sheet START HERE
A1: Ryerson — Services & Solutions Pricing Model v3
A2: PRIVATE INTERNAL. Excel and Google Sheets compatible. Never send this file to a client.
A4: Tab | B4: Name | C4: Purpose | D4: How to use
A5: 1 | B5: Product Catalogue | C5: Every product and standalone phase, with base fee and which drivers move it. | D5: Reference
A6: 2 | B6: Complexity Drivers | C6: Objective, verifiable inputs and their weights. The anti-gaming layer. | D6: Reference
A7: 3 | B7: Quote Calculator | C7: **Work here.** Enter client drivers once; every selected product reprices. | D7: Work here
A8: 4 | B8: Unit Economics | C8: Delivery cost and margin per product. Validate rates before quoting. | D8: Validate
A9: 5 | B9: Client Quote | C9: Print view. Export to PDF. No cost, margin, or driver weights visible. | D9: Export only
A10: 6 | B10: Controls | C10: Margin floors, verification rules, IP boundary. Check before sending. | D10: Check before send
A12: Why one workbook and not one per product
A13: • Separate workbooks drift. The rate card, the complexity weights, and the margin floors must exist once.
A14: • The client never receives this file. Tab 5 is a print view; export it to PDF and send that.
A15: • Amber cells are inputs. Everything else is a formula. Overtyping a formula breaks the Controls checks.
A17: Why the drivers are what they are
A18: • Every driver is externally verifiable or observable during discovery. A client cannot understate headcount or entity count without it surfacing.
A19: • Self-reported subjective inputs (maturity, ambition, readiness) are deliberately excluded from price. They appear only as a pre-work trigger.
A20: • The Frame stage verifies drivers before any fixed price is locked. Quotes issued before Frame are indicative only.
A22: QUOTE GENERATOR
A23: Paste the hosted generator URL here once, then use the link below from any device.
A24: Generator URL | B24: https://REPLACE-ME.example.com/Ryerson_Quote_Generator.html
A25: Open it | B25: =HYPERLINK(B24,"▶ Open the Quote Generator") -> ▶ Open the Quote Generator
A27: • Tapping the link on a phone opens it in Safari or Chrome, which is the only way it will run.
A28: • A link to a file saved on the device will not work. iOS opens local HTML in a preview that cannot run the tool.
A29: • See HOWTO_Host_The_Generator.md for a phone-only way to publish it.

Sheet Product Catalogue
A1: Product Catalogue
A2: Each phase stands alone and carries its own price. Sensitivity shows how much complexity moves the fee.
A4: ID | B4: Line | C4: Product / Phase | D4: Decision or outcome it delivers | E4: Duration | F4: Base fee | G4: Complexity sensitivity | H4: Basis | I4: Status
A5: F01 | B5: Entry | C5: FRAME — Executive Session | D5: Whether to scope at all. Verifies drivers for later fixed pricing. | E5: 0.5–1 day | F5: 11000 | G5: 0.15 | H5: Fixed | I5: ACTIVE
A6: Q00 | B6: Q2C | C6: Q2C Phase 0 — Business Operations Analysis | D6: Current state, BizApp inventory, schema, risk, readiness verdict, tier recommendation. | E6: 3–6 weeks | F6: 5000 | G6: 1 | H6: Driver-based | I6: ACTIVE
A7: Q01 | B7: Q2C | C7: Q2C Standardize & Consolidate | D7: Standardised processes and consolidated data under one system of record. | E7: 4–8 weeks | F7: 25000 | G7: 1 | H7: Driver-based | I7: ACTIVE
A8: Q02 | B8: Q2C | C8: Q2C Process Improvements & Integrations | D8: Gaps filled, integrations designed and delivered, schema stable. | E8: 6–12 weeks | F8: 35000 | G8: 1.15 | H8: Driver-based | I8: ACTIVE
A9: Q03 | B9: Q2C | C9: Q2C System of Systems Implementation | D9: Event-driven architecture, ERP/CLM/middleware, automated compliance. | E9: 12–24 weeks | F9: 50000 | G9: 1.3 | H9: Driver-based | I9: ACTIVE
A10: Q04 | B10: Q2C | C10: Q2C Change Management & Training | D10: Adoption to steady state, role-based training, SMARTER goals for next wave. | E10: 3–6 weeks | F10: 10000 | G10: 0.8 | H10: Driver-based | I10: ACTIVE
A11: A01 | B11: AI Ops | C11: AI Operations MAP | D11: Operating inventory: where AI touches consequential decisions. | E11: 3–5 weeks | F11: 42500 | G11: 1 | H11: Driver-based | I11: ACTIVE
A12: A02 | B12: AI Ops | C12: AI Operations DESIGN | D12: Capacity model and a scale, hold, or redesign call per workflow. | E12: 5–8 weeks | F12: 72500 | G12: 1 | H12: Driver-based | I12: ACTIVE
A13: A03 | B13: AI Ops | C13: AI Operations PROVE | D13: One bounded workflow instrumented and measured against baseline. | E13: 8–16 weeks | F13: 130000 | G13: 1.1 | H13: Driver-based | I13: ACTIVE
A14: S01 | B14: Support | C14: STEWARD — Ongoing Capacity Review | D14: Monthly capacity review as volume, tooling, and risk change. | E14: Monthly | F14: 9000 | G14: 0.5 | H14: Monthly retainer | I14: ACTIVE
A15: S02 | B15: Support | C15: Hypercare (per wave) | D15: Elevated support for 2–4 weeks after a go-live. | E15: 2–4 weeks | F15: 14000 | G15: 0.6 | H15: Fixed per wave | I15: ACTIVE
A16: X01 | B16: Add-on | C16: Modernisation Education Pre-Work | D16: Brings a low-readiness client to a state where analysis is possible. | E16: 1–3 weeks | F16: 18000 | G16: 0.7 | H16: Trigger-based | I16: ACTIVE
... A20: P02 | B20: Product | C20: Benchmark Access | D20: Anonymised comparison against peer cohort. | E20: Annual | F20: 0 | G20: 0 | H20: Subscription | I20: NOT BUILT
A22: Reading the sensitivity column
A23: • 1.00 means the complexity multiplier applies in full. 0.50 means half the multiplier's effect. 0.00 means a genuinely fixed price.
A24: • FRAME is near-fixed at 0.15 because a half-day is a half-day. It is priced to be an easy yes, not to earn.
A25: • System of Systems carries 1.30 because integration count compounds cost faster than headcount does.
A26: • Executive Briefing is 0.00. A briefing for a 60-person company and a 6,000-person company is the same half-day.

Sheet Complexity Drivers
A1: Complexity Drivers
A2: Objective and verifiable. Nothing here relies on client self-assessment. Weights are inputs; verification method is not optional.
A4: Driver | B4: Unit | C4: Baseline | D4: Weight | E4: Cap | F4: How it is verified | G4: Why it drives cost
A5: Employees (FTE) | B5: headcount | C5: 250 | D5: 0.18 | E5: 2.5 | F5: Public filings, LinkedIn, payroll count confirmed at Frame | G5: Stakeholders to interview, processes to map, training population
A6: Legal entities / business units | B6: count | C6: 1 | D6: 0.14 | E6: 2.5 | F6: Corporate registry, org chart confirmed at Frame | G6: Each entity carries its own process variants and data model
A7: Countries of operation | B7: count | C7: 1 | D7: 0.1 | E7: 2 | F7: Public presence, confirmed at Frame | G7: Regulatory variance, language, time zones
A8: Core business applications in scope | B8: count | C8: 8 | D8: 0.2 | E8: 3 | F8: System inventory produced during Frame; licence records | G8: Each app is an integration surface and a data schema
A9: CRM / ERP instances | B9: count | C9: 1 | D9: 0.16 | E9: 2.5 | F9: Admin console screenshot or licence record at Frame | G9: Consolidation effort scales with instance count, not user count
A10: Integrations in scope | B10: count | C10: 6 | D10: 0.16 | E10: 3 | F10: Integration inventory produced during Frame | G10: The single largest cost driver at Tier C
A11: Core data entities in scope | B11: count | C11: 8 | D11: 0.1 | E11: 2 | F11: Schema export or admin inventory at Frame | G11: Migration mapping and validation effort
A12: AI models or frameworks in production | B12: count | C12: 0 | D12: 0.14 | E12: 2.5 | F12: Application inventory and vendor contracts at Frame | G12: Each adds a verification surface and an evidence requirement
A13: Languages in scope | B13: count | C13: 1 | D13: 0.08 | E13: 2 | F13: Observable from public site and system config | G13: Every artifact, test script, and training asset multiplies
A14: Regulated or certified environment | B14: 0 or 1 | C14: 0 | D14: 0.12 | E14: 2 | F14: Certification register, audit reports, contract terms | G14: Evidence standards, audit trail, sign-off depth
A15: Annual transactions through the process | B15: count | C15: 5000 | D15: 0.08 | E15: 2 | F15: System report exported at Frame | G15: Sampling depth and validation volume
A17: Anti-gaming design
A18: • Every driver is externally verifiable or produced as a Frame deliverable. A client who understates entity count creates a discrepancy visible in the org chart.
A19: • No driver is a self-rating. Maturity, ambition, urgency, and readiness never touch the price. Readiness triggers pre-work as a separate line, not a multiplier.
A20: • Caps prevent a single extreme driver from dominating. A 40,000-person company does not cost 160 times a 250-person company.
A21: • Understated drivers discovered after signature trigger a change order at the same rate card. State this in the SOW, not after.

Sheet Quote Calculator
A1: Quote Calculator
A2: Enter client drivers once. Select products. Everything reprices.
A4: CLIENT | C4: CLIENT TAX
A5: Client / opportunity | B5: Shawn Hunter | C5: Province / territory
A6: Date issued | B6: =TODAY() -> 46254 | C6: GST/HST registered? | D6: Yes
A7: Drivers verified at Frame? | B7: No | C7: GST/HST rate | D7: =IF(D6<>"Yes",0,IFERROR(VLOOKUP(D5,Controls!$G$5:$I$17,3,FALSE()),0)) -> 0
A8: Prepared by | B8: Alexander Ryerson | C8: Tax treatment | D8: =IF(D6="Yes",IF(D5="","Select province / territory","Charge "&TEXT(D7,"0%")&" "&IF(OR(D5="Ontario",D5="Nova Scotia",D5="New Brunswick",D5="Newfoundland and Labrador",D5="Prince Edward Island"),"HST","GST")),"Not registered for GST/HST; no HST charged.") -> Select province / territory
A10: DRIVERS — enter actual client values
A11: Driver | B11: Client value | C11: Baseline | D11: Ratio | E11: Weight | F11: Cap | G11: Contribution
A12: ='Complexity Drivers'!A5 -> Employees (FTE) | B12: 50 | C12: ='Complexity Drivers'!C5 -> 250 | D12: =IF(C12<=0,IF(B12>0,1+B12,1),MAX(B12,0)/C12) -> 0.2 | E12: ='Complexity Drivers'!D5 -> 0.18 | F12: ='Complexity Drivers'!E5 -> 2.5 | G12: =E12*(MIN(MAX(D12,0.5),F12)-1) -> -0.09
A13: ='Complexity Drivers'!A6 -> Legal entities / business units | B13: 1 | C13: ='Complexity Drivers'!C6 -> 1 | D13: =IF(C13<=0,IF(B13>0,1+B13,1),MAX(B13,0)/C13) -> 1 | E13: ='Complexity Drivers'!D6 -> 0.14 | F13: ='Complexity Drivers'!E6 -> 2.5 | G13: =E13*(MIN(MAX(D13,0.5),F13)-1) -> 0
A14: ='Complexity Drivers'!A7 -> Countries of operation | B14: 1 | C14: ='Complexity Drivers'!C7 -> 1 | D14: =IF(C14<=0,IF(B14>0,1+B14,1),MAX(B14,0)/C14) -> 1 | E14: ='Complexity Drivers'!D7 -> 0.1 | F14: ='Complexity Drivers'!E7 -> 2 | G14: =E14*(MIN(MAX(D14,0.5),F14)-1) -> 0
A15: ='Complexity Drivers'!A8 -> Core business applications in scope | B15: 3 | C15: ='Complexity Drivers'!C8 -> 8 | D15: =IF(C15<=0,IF(B15>0,1+B15,1),MAX(B15,0)/C15) -> 0.375 | E15: ='Complexity Drivers'!D8 -> 0.2 | F15: ='Complexity Drivers'!E8 -> 3 | G15: =E15*(MIN(MAX(D15,0.5),F15)-1) -> -0.1
A16: ='Complexity Drivers'!A9 -> CRM / ERP instances | B16: 1 | C16: ='Complexity Drivers'!C9 -> 1 | D16: =IF(C16<=0,IF(B16>0,1+B16,1),MAX(B16,0)/C16) -> 1 | E16: ='Complexity Drivers'!D9 -> 0.16 | F16: ='Complexity Drivers'!E9 -> 2.5 | G16: =E16*(MIN(MAX(D16,0.5),F16)-1) -> 0
A17: ='Complexity Drivers'!A10 -> Integrations in scope | B17: 3 | C17: ='Complexity Drivers'!C10 -> 6 | D17: =IF(C17<=0,IF(B17>0,1+B17,1),MAX(B17,0)/C17) -> 0.5 | E17: ='Complexity Drivers'!D10 -> 0.16 | F17: ='Complexity Drivers'!E10 -> 3 | G17: =E17*(MIN(MAX(D17,0.5),F17)-1) -> -0.08
A18: ='Complexity Drivers'!A11 -> Core data entities in scope | B18: 10 | C18: ='Complexity Drivers'!C11 -> 8 | D18: =IF(C18<=0,IF(B18>0,1+B18,1),MAX(B18,0)/C18) -> 1.25 | E18: ='Complexity Drivers'!D11 -> 0.1 | F18: ='Complexity Drivers'!E11 -> 2 | G18: =E18*(MIN(MAX(D18,0.5),F18)-1) -> 0.025
A19: ='Complexity Drivers'!A12 -> AI models or frameworks in production | B19: 0 | C19: ='Complexity Drivers'!C12 -> 0 | D19: =IF(C19<=0,IF(B19>0,1+B19,1),MAX(B19,0)/C19) -> 1 | E19: ='Complexity Drivers'!D12 -> 0.14 | F19: ='Complexity Drivers'!E12 -> 2.5 | G19: =E19*(MIN(MAX(D19,0.5),F19)-1) -> 0
A20: ='Complexity Drivers'!A13 -> Languages in scope | B20: 1 | C20: ='Complexity Drivers'!C13 -> 1 | D20: =IF(C20<=0,IF(B20>0,1+B20,1),MAX(B20,0)/C20) -> 1 | E20: ='Complexity Drivers'!D13 -> 0.08 | F20: ='Complexity Drivers'!E13 -> 2 | G20: =E20*(MIN(MAX(D20,0.5),F20)-1) -> 0
A21: ='Complexity Drivers'!A14 -> Regulated or certified environment | B21: 0 | C21: ='Complexity Drivers'!C14 -> 0 | D21: =IF(C21<=0,IF(B21>0,1+B21,1),MAX(B21,0)/C21) -> 1 | E21: ='Complexity Drivers'!D14 -> 0.12 | F21: ='Complexity Drivers'!E14 -> 2 | G21: =E21*(MIN(MAX(D21,0.5),F21)-1) -> 0
A22: ='Complexity Drivers'!A15 -> Annual transactions through the process | B22: 5000 | C22: ='Complexity Drivers'!C15 -> 5000 | D22: =IF(C22<=0,IF(B22>0,1+B22,1),MAX(B22,0)/C22) -> 1 | E22: ='Complexity Drivers'!D15 -> 0.08 | F22: ='Complexity Drivers'!E15 -> 2 | G22: =E22*(MIN(MAX(D22,0.5),F22)-1) -> 0
A23: Complexity index | G23: =1+SUM(G12:G22) -> 0.755
A24: Bounded multiplier (0.75 to 3.00) | G24: =MIN(MAX(G23,0.75),3) -> 0.755
A26: PRE-WORK TRIGGER
A27: Readiness score from Phase 0 assessment (1–5). Leave blank pre-Frame. | B27: 2
A28: Modernisation education pre-work required? | B28: =IF(B27="","unknown",IF(B27<=2,"RECOMMENDED — may quote separately","not required")) -> RECOMMENDED — may quote separately
A29: Pre-work is a separate line item, never a multiplier. Readiness must not silently inflate the base fee.
A31: PRODUCT SELECTION
A32: Include | B32: ID | C32: Product / Phase | D32: Base fee | E32: Sensitivity | F32: Effective multiplier | G32: Qty | H32: List price | I32: Discount % | J32: Line total
A33: Yes | B33: ='Product Catalogue'!A5 -> F01 | C33: ='Product Catalogue'!C5 -> FRAME — Executive Session | D33: ='Product Catalogue'!F5 -> 11000 | E33: ='Product Catalogue'!G5 -> 0.15 | F33: =1+(G$24-1)*E33 -> 0.96325 | G33: 1 | H33: =IF(A33="Yes",ROUND(D33*F33*G33,-2),0) -> 10600 | I33: 1 | J33: =ROUND(H33*(1-I33),-2) -> 0
A34: Yes | B34: ='Product Catalogue'!A6 -> Q00 | C34: ='Product Catalogue'!C6 -> Q2C Phase 0 — Business Operations Analysis | D34: ='Product Catalogue'!F6 -> 5000 | E34: ='Product Catalogue'!G6 -> 1 | F34: =1+(G$24-1)*E34 -> 0.755 | G34: 1 | H34: =IF(A34="Yes",ROUND(D34*F34*G34,-2),0) -> 3800 | I34: 0 | J34: =ROUND(H34*(1-I34),-2) -> 3800
A35: Yes | B35: ='Product Catalogue'!A7 -> Q01 | C35: ='Product Catalogue'!C7 -> Q2C Standardize & Consolidate | D35: ='Product Catalogue'!F7 -> 25000 | E35: ='Product Catalogue'!G7 -> 1 | F35: =1+(G$24-1)*E35 -> 0.755 | G35: 1 | H35: =IF(A35="Yes",ROUND(D35*F35*G35,-2),0) -> 18900 | I35: 0 | J35: =ROUND(H35*(1-I35),-2) -> 18900
A36: Yes | B36: ='Product Catalogue'!A8 -> Q02 | C36: ='Product Catalogue'!C8 -> Q2C Process Improvements & Integrations | D36: ='Product Catalogue'!F8 -> 35000 | E36: ='Product Catalogue'!G8 -> 1.15 | F36: =1+(G$24-1)*E36 -> 0.71825 | G36: 1 | H36: =IF(A36="Yes",ROUND(D36*F36*G36,-2),0) -> 25100 | I36: 0 | J36: =ROUND(H36*(1-I36),-2) -> 25100
A37: No | B37: ='Product Catalogue'!A9 -> Q03 | C37: ='Product Catalogue'!C9 -> Q2C System of Systems Implementation | D37: ='Product Catalogue'!F9 -> 50000 | E37: ='Product Catalogue'!G9 -> 1.3 | F37: =1+(G$24-1)*E37 -> 0.6815 | G37: 1 | H37: =IF(A37="Yes",ROUND(D37*F37*G37,-2),0) -> 0 | I37: 0 | J37: =ROUND(H37*(1-I37),-2) -> 0
A38: No | B38: ='Product Catalogue'!A10 -> Q04 | C38: ='Product Catalogue'!C10 -> Q2C Change Management & Training | D38: ='Product Catalogue'!F10 -> 10000 | E38: ='Product Catalogue'!G10 -> 0.8 | F38: =1+(G$24-1)*E38 -> 0.804 | G38: 1 | H38: =IF(A38="Yes",ROUND(D38*F38*G38,-2),0) -> 0 | I38: 0 | J38: =ROUND(H38*(1-I38),-2) -> 0
A39: No | B39: ='Product Catalogue'!A11 -> A01 | C39: ='Product Catalogue'!C11 -> AI Operations MAP | D39: ='Product Catalogue'!F11 -> 42500 | E39: ='Product Catalogue'!G11 -> 1 | F39: =1+(G$24-1)*E39 -> 0.755 | G39: 1 | H39: =IF(A39="Yes",ROUND(D39*F39*G39,-2),0) -> 0 | I39: 0 | J39: =ROUND(H39*(1-I39),-2) -> 0
A40: No | B40: ='Product Catalogue'!A12 -> A02 | C40: ='Product Catalogue'!C12 -> AI Operations DESIGN | D40: ='Product Catalogue'!F12 -> 72500 | E40: ='Product Catalogue'!G12 -> 1 | F40: =1+(G$24-1)*E40 -> 0.755 | G40: 1 | H40: =IF(A40="Yes",ROUND(D40*F40*G40,-2),0) -> 0 | I40: 0 | J40: =ROUND(H40*(1-I40),-2) -> 0
A41: No | B41: ='Product Catalogue'!A13 -> A03 | C41: ='Product Catalogue'!C13 -> AI Operations PROVE | D41: ='Product Catalogue'!F13 -> 130000 | E41: ='Product Catalogue'!G13 -> 1.1 | F41: =1+(G$24-1)*E41 -> 0.7305 | G41: 1 | H41: =IF(A41="Yes",ROUND(D41*F41*G41,-2),0) -> 0 | I41: 0 | J41: =ROUND(H41*(1-I41),-2) -> 0
A42: No | B42: ='Product Catalogue'!A14 -> S01 | C42: ='Product Catalogue'!C14 -> STEWARD — Ongoing Capacity Review | D42: ='Product Catalogue'!F14 -> 9000 | E42: ='Product Catalogue'!G14 -> 0.5 | F42: =1+(G$24-1)*E42 -> 0.8775 | G42: 1 | H42: =IF(A42="Yes",ROUND(D42*F42*G42,-2),0) -> 0 | I42: 0 | J42: =ROUND(H42*(1-I42),-2) -> 0
A43: No | B43: ='Product Catalogue'!A15 -> S02 | C43: ='Product Catalogue'!C15 -> Hypercare (per wave) | D43: ='Product Catalogue'!F15 -> 14000 | E43: ='Product Catalogue'!G15 -> 0.6 | F43: =1+(G$24-1)*E43 -> 0.853 | G43: 1 | H43: =IF(A43="Yes",ROUND(D43*F43*G43,-2),0) -> 0 | I43: 0 | J43: =ROUND(H43*(1-I43),-2) -> 0
A44: No | B44: ='Product Catalogue'!A16 -> X01 | C44: ='Product Catalogue'!C16 -> Modernisation Education Pre-Work | D44: ='Product Catalogue'!F16 -> 18000 | E44: ='Product Catalogue'!G16 -> 0.7 | F44: =1+(G$24-1)*E44 -> 0.8285 | G44: 1 | H44: =IF(A44="Yes",ROUND(D44*F44*G44,-2),0) -> 0 | I44: 0 | J44: =ROUND(H44*(1-I44),-2) -> 0
...

Sheet Unit Economics
A1: Unit Economics
A2: Delivery days at BASELINE complexity. Rates are UNVALIDATED assumptions — confirm before quoting.
A4: ID | B4: Product / Phase | C4: Baseline days | D4: Base fee | E4: Baseline cost | F4: Baseline margin %
A5: ='Product Catalogue'!A5 -> F01 | B5: ='Product Catalogue'!C5 -> FRAME — Executive Session | C5: 2 | D5: ='Product Catalogue'!F5 -> 11000 | E5: =C5*$D$28 -> 1918.655 | F5: =IF(D5=0,0,(D5-E5)/D5) -> 0.82557681
A6: ='Product Catalogue'!A6 -> Q00 | B6: ='Product Catalogue'!C6 -> Q2C Phase 0 — Business Operations Analysis | C6: 26 | D6: ='Product Catalogue'!F6 -> 5000 | E6: =C6*$D$28 -> 24942.516 | F6: =IF(D6=0,0,(D6-E6)/D6) -> -3.9885031
A7: ='Product Catalogue'!A7 -> Q01 | B7: ='Product Catalogue'!C7 -> Q2C Standardize & Consolidate | C7: 32 | D7: ='Product Catalogue'!F7 -> 25000 | E7: =C7*$D$28 -> 30698.481 | F7: =IF(D7=0,0,(D7-E7)/D7) -> -0.22793922
A8: ='Product Catalogue'!A8 -> Q02 | B8: ='Product Catalogue'!C8 -> Q2C Process Improvements & Integrations | C8: 48 | D8: ='Product Catalogue'!F8 -> 35000 | E8: =C8*$D$28 -> 46047.721 | F8: =IF(D8=0,0,(D8-E8)/D8) -> -0.31564917
A9: ='Product Catalogue'!A9 -> Q03 | B9: ='Product Catalogue'!C9 -> Q2C System of Systems Implementation | C9: 92 | D9: ='Product Catalogue'!F9 -> 50000 | E9: =C9*$D$28 -> 88258.132 | F9: =IF(D9=0,0,(D9-E9)/D9) -> -0.76516264
A10: ='Product Catalogue'!A10 -> Q04 | B10: ='Product Catalogue'!C10 -> Q2C Change Management & Training | C10: 20 | D10: ='Product Catalogue'!F10 -> 10000 | E10: =C10*$D$28 -> 19186.55 | F10: =IF(D10=0,0,(D10-E10)/D10) -> -0.91865504
A11: ='Product Catalogue'!A11 -> A01 | B11: ='Product Catalogue'!C11 -> AI Operations MAP | C11: 22 | D11: ='Product Catalogue'!F11 -> 42500 | E11: =C11*$D$28 -> 21105.205 | F11: =IF(D11=0,0,(D11-E11)/D11) -> 0.50340693
A12: ='Product Catalogue'!A12 -> A02 | B12: ='Product Catalogue'!C12 -> AI Operations DESIGN | C12: 30 | D12: ='Product Catalogue'!F12 -> 72500 | E12: =C12*$D$28 -> 28779.826 | F12: =IF(D12=0,0,(D12-E12)/D12) -> 0.60303689
A13: ='Product Catalogue'!A13 -> A03 | B13: ='Product Catalogue'!C13 -> AI Operations PROVE | C13: 58 | D13: ='Product Catalogue'!F13 -> 130000 | E13: =C13*$D$28 -> 55640.996 | F13: =IF(D13=0,0,(D13-E13)/D13) -> 0.57199234
A14: ='Product Catalogue'!A14 -> S01 | B14: ='Product Catalogue'!C14 -> STEWARD — Ongoing Capacity Review | C14: 4 | D14: ='Product Catalogue'!F14 -> 9000 | E14: =C14*$D$28 -> 3837.3101 | F14: =IF(D14=0,0,(D14-E14)/D14) -> 0.57363221
A15: ='Product Catalogue'!A15 -> S02 | B15: ='Product Catalogue'!C15 -> Hypercare (per wave) | C15: 7 | D15: ='Product Catalogue'!F15 -> 14000 | E15: =C15*$D$28 -> 6715.2926 | F15: =IF(D15=0,0,(D15-E15)/D15) -> 0.52033624
A16: ='Product Catalogue'!A16 -> X01 | B16: ='Product Catalogue'!C16 -> Modernisation Education Pre-Work | C16: 9 | D16: ='Product Catalogue'!F16 -> 18000 | E16: =C16*$D$28 -> 8633.9477 | F16: =IF(D16=0,0,(D16-E16)/D16) -> 0.52033624
... A20: ='Product Catalogue'!A20 -> P02 | B20: ='Product Catalogue'!C20 -> Benchmark Access | C20: 0 | D20: ='Product Catalogue'!F20 -> 0 | E20: =C20*$D$28 -> 0 | F20: =IF(D20=0,0,(D20-E20)/D20) -> 0
A22: ROLE COSTS
A23: Role | B23: Annual loaded cost | C23: Delivery days/year | D23: Cost per day | E23: Mix % | F23: Confidence
A24: Principal / executive lead | B24: 253000 | C24: 200 | D24: =IF(C24=0,0,B24/C24) -> 1265 | E24: 0.45 | F24: UNVALIDATED
A25: Senior AI operations lead | B25: 176000 | C25: 210 | D25: =IF(C25=0,0,B25/C25) -> 838.09524 | E25: 0.35 | F25: UNVALIDATED
A26: Analyst / delivery support | B26: 104000 | C26: 215 | D26: =IF(C26=0,0,B26/C26) -> 483.72093 | E26: 0.2 | F26: UNVALIDATED
A27: Mix check (must be 100%) | E27: =SUM(E24:E26) -> 1
A28: BLENDED COST PER DAY | D28: =SUMPRODUCT(D24:D26,E24:E26) -> 959.32752

Sheet Client Quote
A1: Proposed Engagement
A2: Print view. Export to PDF. Contains no cost, margin, driver weight, or rate data.
A4: Prepared for | B4: ='Quote Calculator'!B5 -> Shawn Hunter
A5: Date issued | B5: ='Quote Calculator'!B6 -> 46254
A6: Prepared by | B6: ='Quote Calculator'!B8 -> Alexander Ryerson
A8: Phase | B8: What it delivers | C8: Duration | D8: Sales Cost | E8: Investment
A9: =IF('Quote Calculator'!A33="Yes",'Product Catalogue'!C5,"") -> FRAME — Executive Session | B9: =IF('Quote Calculator'!A33="Yes",'Product Catalogue'!D5,"") -> Whether to scope at all. Verifies drivers for later fixed pricing. | C9: =IF('Quote Calculator'!A33="Yes",'Product Catalogue'!E5,"") -> 0.5–1 day | D9: =IF('Quote Calculator'!A33="Yes",'Quote Calculator'!H33,"") -> 10600 | E9: =IF('Quote Calculator'!A33="Yes",'Quote Calculator'!J33,"") -> 0
A10: =IF('Quote Calculator'!A34="Yes",'Product Catalogue'!C6,"") -> Q2C Phase 0 — Business Operations Analysis | B10: =IF('Quote Calculator'!A34="Yes",'Product Catalogue'!D6,"") -> Current state, BizApp inventory, schema, risk, readiness verdict, tier recommendation. | C10: =IF('Quote Calculator'!A34="Yes",'Product Catalogue'!E6,"") -> 3–6 weeks | D10: =IF('Quote Calculator'!A34="Yes",'Quote Calculator'!H34,"") -> 3800 | E10: =IF('Quote Calculator'!A34="Yes",'Quote Calculator'!J34,"") -> 3800
A11: =IF('Quote Calculator'!A35="Yes",'Product Catalogue'!C7,"") -> Q2C Standardize & Consolidate | B11: =IF('Quote Calculator'!A35="Yes",'Product Catalogue'!D7,"") -> Standardised processes and consolidated data under one system of record. | C11: =IF('Quote Calculator'!A35="Yes",'Product Catalogue'!E7,"") -> 4–8 weeks | D11: =IF('Quote Calculator'!A35="Yes",'Quote Calculator'!H35,"") -> 18900 | E11: =IF('Quote Calculator'!A35="Yes",'Quote Calculator'!J35,"") -> 18900
A12: =IF('Quote Calculator'!A36="Yes",'Product Catalogue'!C8,"") -> Q2C Process Improvements & Integrations | B12: =IF('Quote Calculator'!A36="Yes",'Product Catalogue'!D8,"") -> Gaps filled, integrations designed and delivered, schema stable. | C12: =IF('Quote Calculator'!A36="Yes",'Product Catalogue'!E8,"") -> 6–12 weeks | D12: =IF('Quote Calculator'!A36="Yes",'Quote Calculator'!H36,"") -> 25100 | E12: =IF('Quote Calculator'!A36="Yes",'Quote Calculator'!J36,"") -> 25100
A13: =IF('Quote Calculator'!A37="Yes",'Product Catalogue'!C9,"") | B13: =IF('Quote Calculator'!A37="Yes",'Product Catalogue'!D9,"") | C13: =IF('Quote Calculator'!A37="Yes",'Product Catalogue'!E9,"") | D13: =IF('Quote Calculator'!A37="Yes",'Quote Calculator'!H37,"") | E13: =IF('Quote Calculator'!A37="Yes",'Quote Calculator'!J37,"")
A14: =IF('Quote Calculator'!A38="Yes",'Product Catalogue'!C10,"") | B14: =IF('Quote Calculator'!A38="Yes",'Product Catalogue'!D10,"") | C14: =IF('Quote Calculator'!A38="Yes",'Product Catalogue'!E10,"") | D14: =IF('Quote Calculator'!A38="Yes",'Quote Calculator'!H38,"") | E14: =IF('Quote Calculator'!A38="Yes",'Quote Calculator'!J38,"")
A15: =IF('Quote Calculator'!A39="Yes",'Product Catalogue'!C11,"") | B15: =IF('Quote Calculator'!A39="Yes",'Product Catalogue'!D11,"") | C15: =IF('Quote Calculator'!A39="Yes",'Product Catalogue'!E11,"") | D15: =IF('Quote Calculator'!A39="Yes",'Quote Calculator'!H39,"") | E15: =IF('Quote Calculator'!A39="Yes",'Quote Calculator'!J39,"")
A16: =IF('Quote Calculator'!A40="Yes",'Product Catalogue'!C12,"") | B16: =IF('Quote Calculator'!A40="Yes",'Product Catalogue'!D12,"") | C16: =IF('Quote Calculator'!A40="Yes",'Product Catalogue'!E12,"") | D16: =IF('Quote Calculator'!A40="Yes",'Quote Calculator'!H40,"") | E16: =IF('Quote Calculator'!A40="Yes",'Quote Calculator'!J40,"")
A17: =IF('Quote Calculator'!A41="Yes",'Product Catalogue'!C13,"") | B17: =IF('Quote Calculator'!A41="Yes",'Product Catalogue'!D13,"") | C17: =IF('Quote Calculator'!A41="Yes",'Product Catalogue'!E13,"") | D17: =IF('Quote Calculator'!A41="Yes",'Quote Calculator'!H41,"") | E17: =IF('Quote Calculator'!A41="Yes",'Quote Calculator'!J41,"")
A18: =IF('Quote Calculator'!A42="Yes",'Product Catalogue'!C14,"") | B18: =IF('Quote Calculator'!A42="Yes",'Product Catalogue'!D14,"") | C18: =IF('Quote Calculator'!A42="Yes",'Product Catalogue'!E14,"") | D18: =IF('Quote Calculator'!A42="Yes",'Quote Calculator'!H42,"") | E18: =IF('Quote Calculator'!A42="Yes",'Quote Calculator'!J42,"")
A19: =IF('Quote Calculator'!A43="Yes",'Product Catalogue'!C15,"") | B19: =IF('Quote Calculator'!A43="Yes",'Product Catalogue'!D15,"") | C19: =IF('Quote Calculator'!A43="Yes",'Product Catalogue'!E15,"") | D19: =IF('Quote Calculator'!A43="Yes",'Quote Calculator'!H43,"") | E19: =IF('Quote Calculator'!A43="Yes",'Quote Calculator'!J43,"")
A20: =IF('Quote Calculator'!A44="Yes",'Product Catalogue'!C16,"") | B20: =IF('Quote Calculator'!A44="Yes",'Product Catalogue'!D16,"") | C20: =IF('Quote Calculator'!A44="Yes",'Product Catalogue'!E16,"") | D20: =IF('Quote Calculator'!A44="Yes",'Quote Calculator'!H44,"") | E20: =IF('Quote Calculator'!A44="Yes",'Quote Calculator'!J44,"")
... A24: =IF('Quote Calculator'!A48="Yes",'Product Catalogue'!C20,"") | B24: =IF('Quote Calculator'!A48="Yes",'Product Catalogue'!D20,"") | C24: =IF('Quote Calculator'!A48="Yes",'Product Catalogue'!E20,"") | D24: =IF('Quote Calculator'!A48="Yes",'Quote Calculator'!H48,"") | E24: =IF('Quote Calculator'!A48="Yes",'Quote Calculator'!J48,"")
C25: Subtotal | E25: ='Quote Calculator'!J51 -> 47800
C26: =IF('Quote Calculator'!D6="Yes",IF(OR('Quote Calculator'!D5="Ontario",'Quote Calculator'!D5="Nova Scotia",'Quote Calculator'!D5="New Brunswick",'Quote Calculator'!D5="Newfoundland and Labrador",'Quote Calculator'!D5="Prince Edward Island"),"HST","GST"),"GST/HST") -> GST | E26: =ROUND(E25*'Quote Calculator'!D7,2) -> 0
C27: Total investment | E27: =E25+E26 -> 47800
A29: Terms
A30: =IF('Quote Calculator'!D6="Yes","• GST/HST is calculated using the client province or territory and added where required by law.","• Not registered for GST/HST; no HST charged.") -> • GST/HST is calculated using the client province or territory and added where required by law.
A31: • Each phase stands alone. Each earns the next. Stop at any phase boundary.
A32: • Pricing reflects the operating scale confirmed during the Frame session. Material differences in entity count, application count, or integration scope discovered after signature are handled by change order at the same rates.
A33: • 50% due at phase kickoff, 50% at phase completion and sponsor sign-off.
A34: • If the operating cost we identify in Phase 0 does not exceed the proposed fee, the honest recommendation is to stop.

Sheet Controls
A1: Controls | G1: CANADIAN GST/HST LOOKUP
A2: Check before any quote leaves. HARD controls are stop conditions. | G2: GST/HST rates current on 2026-08-20. Verify current rules before issuing: https://www.canada.ca/en/revenue-agency/services/tax/businesses/topics/gst-hst-businesses/charge-collect-which-rate/calculator.html
A4: ID | B4: Control | C4: Where | D4: Rule | E4: Type | G4: Province / territory | H4: Tax type | I4: Rate | J4: IMPORTANT
A5: C01 | B5: Gross margin at or above 45% | C5: Quote Calculator | D5: Written rationale below 45%. Decline below 35%. | E5: HARD | G5: Alberta | H5: GST | I5: 0.05 | J5: BC PST, Manitoba RST, Quebec QST and Saskatchewan PST are separate regimes. They are not auto-added merely from province selection; confirm registration and service-taxability obligations separately.
A6: C02 | B6: Drivers verified at Frame | C6: Quote Calculator | D6: Unverified drivers make the quote indicative only. Never issue a fixed price on unverified inputs. | E6: HARD | G6: British Columbia | H6: GST | I6: 0.05
A7: C03 | B7: Role mix sums to 100% | C7: Unit Economics | D7: Blended cost is wrong otherwise | E7: HARD | G7: Manitoba | H7: GST | I7: 0.05
A8: C04 | B8: Rates validated against actual delivery | C8: Unit Economics | D8: All three roles currently UNVALIDATED | E8: HARD | G8: New Brunswick | H8: HST | I8: 0.15
A9: C05 | B9: No product lines quoted | C9: Product Catalogue | D9: Capacity Calculator and Benchmark are NOT BUILT | E9: HARD | G9: Newfoundland and Labrador | H9: HST | I9: 0.15
A10: C06 | B10: Client Quote contains no cost or weight data | C10: Client Quote | D10: Export the print view only. Never send the workbook. | E10: HARD | G10: Northwest Territories | H10: GST | I10: 0.05
A11: C07 | B11: Readiness handled as pre-work, not multiplier | C11: Quote Calculator | D11: Recommend pre-work when readiness is 2 or lower. It may be quoted separately and must not block the current quote. | E11: SOFT | G11: Nova Scotia | H11: HST | I11: 0.14
A12: C08 | B12: Discount within 10% | C12: Quote Calculator | D12: Above 10% requires recorded rationale | E12: SOFT | G12: Nunavut | H12: GST | I12: 0.05
A13: C09 | B13: Complexity multiplier within 0.75–3.00 | C13: Quote Calculator | D13: Outside the band means a driver is wrong or the engagement is not standard | E13: SOFT | G13: Ontario | H13: HST | I13: 0.13
G14: Prince Edward Island | H14: HST | I14: 0.15
A15: IP boundary | G15: Quebec | H15: GST | I15: 0.05
A16: May be shared | B16: Never shared | G16: Saskatchewan | H16: GST | I16: 0.05
A17: Phase names, what each delivers, duration, total investment, terms | B17: Driver weights, complexity multiplier, rate card, delivery days, margins, this workbook | G17: Yukon | H17: GST | I17: 0.05
